<?xml version="1.0"?>

<robot xmlns:xacro="http://www.ros.org/wiki/xacro">

  <xacro:macro name="wam2" params="parent">

    <link name="wam_link2">
        <inertial>
            <origin xyz="0 0 0" rpy="0 0 0" />
             <mass value="4.8487" />
            <inertia  ixx="1.0" ixy="0.0"  ixz="0.0"  iyy="0.1"  iyz="0.0"  izz="0.1" />
        </inertial>
        <visual>
            <origin xyz="0.0 0.0 0.0" rpy="0 0 0" />
            <geometry name="wam_link2_visual">
                <mesh filename="package://iit_wamcyclope_description/mesh/wam2.stl" scale="1.0 1.0 1.0" />
            </geometry>
            <material name="grey_blue" >
                <color rgba="0.4 0.4 1.0 1"/>
            </material>
        </visual>
        <collision>
            <origin xyz="0.0 0.0 0.0" rpy="0 0 0"/>
            <geometry name="wam_link2_collision">
                <mesh filename="package://iit_wamcyclope_description/mesh/wam2.stl" scale="1.0 1.0 1.0" />
<!--                <box size="0.10 0.10 0.10"/> -->
            </geometry>
            <contact_coefficients kd="1.0" kp="1000.0" mu="0"/>
        </collision>
    </link>
    <gazebo reference="wam_link2">
        <material>Gazebo/Grey</material>
        <selfCollide>true</selfCollide>
    </gazebo>

    <joint name="wam_j2" type="revolute">
        <parent link="${parent}"/>
        <child link="wam_link2"/>
        <origin xyz="0.0 0.0 0.0" rpy="0 0 0" />
        <axis xyz="0 1 0" />
        <limit lower="-2.0" upper="2.0" effort="30" velocity="2.0"/>
        <!--<safety_controller k_velocity="0.5"/>-->
        <dynamics damping="100"/>
    </joint>

    <transmission type="pr2_mechanism_model/SimpleTransmission" name="j2_transmission">
      <actuator name="j2" />
      <joint name="wam_j2" />
      <mechanicalReduction>1</mechanicalReduction>
      <motorTorqueConstant>1</motorTorqueConstant>
      <!--<pulsesPerRevolution>90000</pulsesPerRevolution>-->
    </transmission>

  </xacro:macro>

</robot>
